/bin/sh: env/bin/bench: No such file or directory
Backup failed for Site library.test. Database or site_config.json may be corrupted
Traceback (most recent call last):
  File "apps/frappe/frappe/commands/site.py", line 580, in backup
    odb = scheduled_backup(
  File "apps/frappe/frappe/utils/backups.py", line 552, in scheduled_backup
    odb = new_backup(
  File "apps/frappe/frappe/utils/backups.py", line 604, in new_backup
    odb.get_backup(older_than, ignore_files, force=force)
  File "apps/frappe/frappe/utils/backups.py", line 195, in get_backup
    self.take_dump()
  File "apps/frappe/frappe/utils/backups.py", line 390, in take_dump
    frappe.throw(
  File "apps/frappe/frappe/__init__.py", line 449, in throw
    msgprint(msg, raise_exception=exc, title=title, indicator='red', is_minimizable=is_minimizable, wide=wide, as_list=as_list)
  File "apps/frappe/frappe/__init__.py", line 428, in msgprint
    _raise_exception()
  File "apps/frappe/frappe/__init__.py", line 383, in _raise_exception
    raise raise_exception(msg)
frappe.exceptions.ExecutableNotFound: mysqldump not found in PATH! This is required to take a backup.

/bin/sh: env/bin/bench: No such file or directory
Backup failed for Site library.test. Database or site_config.json may be corrupted
Traceback (most recent call last):
  File "apps/frappe/frappe/commands/site.py", line 580, in backup
    odb = scheduled_backup(
  File "apps/frappe/frappe/utils/backups.py", line 552, in scheduled_backup
    odb = new_backup(
  File "apps/frappe/frappe/utils/backups.py", line 604, in new_backup
    odb.get_backup(older_than, ignore_files, force=force)
  File "apps/frappe/frappe/utils/backups.py", line 195, in get_backup
    self.take_dump()
  File "apps/frappe/frappe/utils/backups.py", line 390, in take_dump
    frappe.throw(
  File "apps/frappe/frappe/__init__.py", line 449, in throw
    msgprint(msg, raise_exception=exc, title=title, indicator='red', is_minimizable=is_minimizable, wide=wide, as_list=as_list)
  File "apps/frappe/frappe/__init__.py", line 428, in msgprint
    _raise_exception()
  File "apps/frappe/frappe/__init__.py", line 383, in _raise_exception
    raise raise_exception(msg)
frappe.exceptions.ExecutableNotFound: mysqldump not found in PATH! This is required to take a backup.

/bin/sh: env/bin/bench: No such file or directory
Backup failed for Site library.test. Database or site_config.json may be corrupted
Traceback (most recent call last):
  File "apps/frappe/frappe/commands/site.py", line 580, in backup
    odb = scheduled_backup(
  File "apps/frappe/frappe/utils/backups.py", line 552, in scheduled_backup
    odb = new_backup(
  File "apps/frappe/frappe/utils/backups.py", line 604, in new_backup
    odb.get_backup(older_than, ignore_files, force=force)
  File "apps/frappe/frappe/utils/backups.py", line 195, in get_backup
    self.take_dump()
  File "apps/frappe/frappe/utils/backups.py", line 390, in take_dump
    frappe.throw(
  File "apps/frappe/frappe/__init__.py", line 449, in throw
    msgprint(msg, raise_exception=exc, title=title, indicator='red', is_minimizable=is_minimizable, wide=wide, as_list=as_list)
  File "apps/frappe/frappe/__init__.py", line 428, in msgprint
    _raise_exception()
  File "apps/frappe/frappe/__init__.py", line 383, in _raise_exception
    raise raise_exception(msg)
frappe.exceptions.ExecutableNotFound: mysqldump not found in PATH! This is required to take a backup.

/bin/sh: env/bin/bench: No such file or directory
Backup failed for Site library.test. Database or site_config.json may be corrupted
Traceback (most recent call last):
  File "apps/frappe/frappe/commands/site.py", line 580, in backup
    odb = scheduled_backup(
  File "apps/frappe/frappe/utils/backups.py", line 552, in scheduled_backup
    odb = new_backup(
  File "apps/frappe/frappe/utils/backups.py", line 604, in new_backup
    odb.get_backup(older_than, ignore_files, force=force)
  File "apps/frappe/frappe/utils/backups.py", line 195, in get_backup
    self.take_dump()
  File "apps/frappe/frappe/utils/backups.py", line 390, in take_dump
    frappe.throw(
  File "apps/frappe/frappe/__init__.py", line 449, in throw
    msgprint(msg, raise_exception=exc, title=title, indicator='red', is_minimizable=is_minimizable, wide=wide, as_list=as_list)
  File "apps/frappe/frappe/__init__.py", line 428, in msgprint
    _raise_exception()
  File "apps/frappe/frappe/__init__.py", line 383, in _raise_exception
    raise raise_exception(msg)
frappe.exceptions.ExecutableNotFound: mysqldump not found in PATH! This is required to take a backup.

/bin/sh: env/bin/bench: No such file or directory
Backup failed for Site library.test. Database or site_config.json may be corrupted
Traceback (most recent call last):
  File "apps/frappe/frappe/commands/site.py", line 580, in backup
    odb = scheduled_backup(
  File "apps/frappe/frappe/utils/backups.py", line 552, in scheduled_backup
    odb = new_backup(
  File "apps/frappe/frappe/utils/backups.py", line 586, in new_backup
    odb = BackupGenerator(
  File "apps/frappe/frappe/utils/backups.py", line 87, in __init__
    self.setup_backup_tables()
  File "apps/frappe/frappe/utils/backups.py", line 121, in setup_backup_tables
    existing_tables = frappe.db.get_tables()
  File "apps/frappe/frappe/database/database.py", line 879, in get_tables
    table_rows = self.sql("""
  File "apps/frappe/frappe/database/database.py", line 130, in sql
    self.connect()
  File "apps/frappe/frappe/database/database.py", line 75, in connect
    self._conn = self.get_connection()
  File "apps/frappe/frappe/database/mariadb/database.py", line 75, in get_connection
    conn = pymysql.connect(
  File "env/lib/python3.9/site-packages/pymysql/connections.py", line 353, in __init__
    self.connect()
  File "env/lib/python3.9/site-packages/pymysql/connections.py", line 633, in connect
    self._request_authentication()
  File "env/lib/python3.9/site-packages/pymysql/connections.py", line 907, in _request_authentication
    auth_packet = self._read_packet()
  File "env/lib/python3.9/site-packages/pymysql/connections.py", line 725, in _read_packet
    packet.raise_for_error()
  File "env/lib/python3.9/site-packages/pymysql/protocol.py", line 221, in raise_for_error
    err.raise_mysql_exception(self._data)
  File "env/lib/python3.9/site-packages/pymysql/err.py", line 143, in raise_mysql_exception
    raise errorclass(errno, errval)
pymysql.err.OperationalError: (1045, "Access denied for user '_95acf9e769041055'@'localhost' (using password: YES)")

/bin/sh: env/bin/bench: No such file or directory
Backup failed for Site library.test. Database or site_config.json may be corrupted
Traceback (most recent call last):
  File "apps/frappe/frappe/commands/site.py", line 580, in backup
    odb = scheduled_backup(
  File "apps/frappe/frappe/utils/backups.py", line 552, in scheduled_backup
    odb = new_backup(
  File "apps/frappe/frappe/utils/backups.py", line 586, in new_backup
    odb = BackupGenerator(
  File "apps/frappe/frappe/utils/backups.py", line 87, in __init__
    self.setup_backup_tables()
  File "apps/frappe/frappe/utils/backups.py", line 121, in setup_backup_tables
    existing_tables = frappe.db.get_tables()
  File "apps/frappe/frappe/database/database.py", line 879, in get_tables
    table_rows = self.sql("""
  File "apps/frappe/frappe/database/database.py", line 130, in sql
    self.connect()
  File "apps/frappe/frappe/database/database.py", line 75, in connect
    self._conn = self.get_connection()
  File "apps/frappe/frappe/database/mariadb/database.py", line 75, in get_connection
    conn = pymysql.connect(
  File "env/lib/python3.9/site-packages/pymysql/connections.py", line 353, in __init__
    self.connect()
  File "env/lib/python3.9/site-packages/pymysql/connections.py", line 633, in connect
    self._request_authentication()
  File "env/lib/python3.9/site-packages/pymysql/connections.py", line 907, in _request_authentication
    auth_packet = self._read_packet()
  File "env/lib/python3.9/site-packages/pymysql/connections.py", line 725, in _read_packet
    packet.raise_for_error()
  File "env/lib/python3.9/site-packages/pymysql/protocol.py", line 221, in raise_for_error
    err.raise_mysql_exception(self._data)
  File "env/lib/python3.9/site-packages/pymysql/err.py", line 143, in raise_mysql_exception
    raise errorclass(errno, errval)
pymysql.err.OperationalError: (1045, "Access denied for user '_95acf9e769041055'@'localhost' (using password: YES)")

/bin/sh: env/bin/bench: No such file or directory
Backup failed for Site library.test. Database or site_config.json may be corrupted
Traceback (most recent call last):
  File "apps/frappe/frappe/commands/site.py", line 580, in backup
    odb = scheduled_backup(
  File "apps/frappe/frappe/utils/backups.py", line 552, in scheduled_backup
    odb = new_backup(
  File "apps/frappe/frappe/utils/backups.py", line 586, in new_backup
    odb = BackupGenerator(
  File "apps/frappe/frappe/utils/backups.py", line 87, in __init__
    self.setup_backup_tables()
  File "apps/frappe/frappe/utils/backups.py", line 121, in setup_backup_tables
    existing_tables = frappe.db.get_tables()
  File "apps/frappe/frappe/database/database.py", line 879, in get_tables
    table_rows = self.sql("""
  File "apps/frappe/frappe/database/database.py", line 130, in sql
    self.connect()
  File "apps/frappe/frappe/database/database.py", line 75, in connect
    self._conn = self.get_connection()
  File "apps/frappe/frappe/database/mariadb/database.py", line 75, in get_connection
    conn = pymysql.connect(
  File "env/lib/python3.9/site-packages/pymysql/connections.py", line 353, in __init__
    self.connect()
  File "env/lib/python3.9/site-packages/pymysql/connections.py", line 633, in connect
    self._request_authentication()
  File "env/lib/python3.9/site-packages/pymysql/connections.py", line 907, in _request_authentication
    auth_packet = self._read_packet()
  File "env/lib/python3.9/site-packages/pymysql/connections.py", line 725, in _read_packet
    packet.raise_for_error()
  File "env/lib/python3.9/site-packages/pymysql/protocol.py", line 221, in raise_for_error
    err.raise_mysql_exception(self._data)
  File "env/lib/python3.9/site-packages/pymysql/err.py", line 143, in raise_mysql_exception
    raise errorclass(errno, errval)
pymysql.err.OperationalError: (1045, "Access denied for user '_95acf9e769041055'@'localhost' (using password: YES)")

/bin/sh: env/bin/bench: No such file or directory
Backup failed for Site library.test. Database or site_config.json may be corrupted
Traceback (most recent call last):
  File "apps/frappe/frappe/commands/site.py", line 580, in backup
    odb = scheduled_backup(
  File "apps/frappe/frappe/utils/backups.py", line 552, in scheduled_backup
    odb = new_backup(
  File "apps/frappe/frappe/utils/backups.py", line 586, in new_backup
    odb = BackupGenerator(
  File "apps/frappe/frappe/utils/backups.py", line 87, in __init__
    self.setup_backup_tables()
  File "apps/frappe/frappe/utils/backups.py", line 121, in setup_backup_tables
    existing_tables = frappe.db.get_tables()
  File "apps/frappe/frappe/database/database.py", line 879, in get_tables
    table_rows = self.sql("""
  File "apps/frappe/frappe/database/database.py", line 130, in sql
    self.connect()
  File "apps/frappe/frappe/database/database.py", line 75, in connect
    self._conn = self.get_connection()
  File "apps/frappe/frappe/database/mariadb/database.py", line 75, in get_connection
    conn = pymysql.connect(
  File "env/lib/python3.9/site-packages/pymysql/connections.py", line 353, in __init__
    self.connect()
  File "env/lib/python3.9/site-packages/pymysql/connections.py", line 633, in connect
    self._request_authentication()
  File "env/lib/python3.9/site-packages/pymysql/connections.py", line 907, in _request_authentication
    auth_packet = self._read_packet()
  File "env/lib/python3.9/site-packages/pymysql/connections.py", line 725, in _read_packet
    packet.raise_for_error()
  File "env/lib/python3.9/site-packages/pymysql/protocol.py", line 221, in raise_for_error
    err.raise_mysql_exception(self._data)
  File "env/lib/python3.9/site-packages/pymysql/err.py", line 143, in raise_mysql_exception
    raise errorclass(errno, errval)
pymysql.err.OperationalError: (1045, "Access denied for user '_95acf9e769041055'@'localhost' (using password: YES)")

/bin/sh: env/bin/bench: No such file or directory
Backup failed for Site library.test. Database or site_config.json may be corrupted
Traceback (most recent call last):
  File "apps/frappe/frappe/commands/site.py", line 580, in backup
    odb = scheduled_backup(
  File "apps/frappe/frappe/utils/backups.py", line 552, in scheduled_backup
    odb = new_backup(
  File "apps/frappe/frappe/utils/backups.py", line 586, in new_backup
    odb = BackupGenerator(
  File "apps/frappe/frappe/utils/backups.py", line 87, in __init__
    self.setup_backup_tables()
  File "apps/frappe/frappe/utils/backups.py", line 121, in setup_backup_tables
    existing_tables = frappe.db.get_tables()
  File "apps/frappe/frappe/database/database.py", line 879, in get_tables
    table_rows = self.sql("""
  File "apps/frappe/frappe/database/database.py", line 130, in sql
    self.connect()
  File "apps/frappe/frappe/database/database.py", line 75, in connect
    self._conn = self.get_connection()
  File "apps/frappe/frappe/database/mariadb/database.py", line 75, in get_connection
    conn = pymysql.connect(
  File "env/lib/python3.9/site-packages/pymysql/connections.py", line 353, in __init__
    self.connect()
  File "env/lib/python3.9/site-packages/pymysql/connections.py", line 633, in connect
    self._request_authentication()
  File "env/lib/python3.9/site-packages/pymysql/connections.py", line 907, in _request_authentication
    auth_packet = self._read_packet()
  File "env/lib/python3.9/site-packages/pymysql/connections.py", line 725, in _read_packet
    packet.raise_for_error()
  File "env/lib/python3.9/site-packages/pymysql/protocol.py", line 221, in raise_for_error
    err.raise_mysql_exception(self._data)
  File "env/lib/python3.9/site-packages/pymysql/err.py", line 143, in raise_mysql_exception
    raise errorclass(errno, errval)
pymysql.err.OperationalError: (1045, "Access denied for user '_95acf9e769041055'@'localhost' (using password: YES)")

/bin/sh: env/bin/bench: No such file or directory
Backup failed for Site library.test. Database or site_config.json may be corrupted
Traceback (most recent call last):
  File "apps/frappe/frappe/commands/site.py", line 580, in backup
    odb = scheduled_backup(
  File "apps/frappe/frappe/utils/backups.py", line 552, in scheduled_backup
    odb = new_backup(
  File "apps/frappe/frappe/utils/backups.py", line 586, in new_backup
    odb = BackupGenerator(
  File "apps/frappe/frappe/utils/backups.py", line 87, in __init__
    self.setup_backup_tables()
  File "apps/frappe/frappe/utils/backups.py", line 121, in setup_backup_tables
    existing_tables = frappe.db.get_tables()
  File "apps/frappe/frappe/database/database.py", line 879, in get_tables
    table_rows = self.sql("""
  File "apps/frappe/frappe/database/database.py", line 130, in sql
    self.connect()
  File "apps/frappe/frappe/database/database.py", line 75, in connect
    self._conn = self.get_connection()
  File "apps/frappe/frappe/database/mariadb/database.py", line 75, in get_connection
    conn = pymysql.connect(
  File "env/lib/python3.9/site-packages/pymysql/connections.py", line 353, in __init__
    self.connect()
  File "env/lib/python3.9/site-packages/pymysql/connections.py", line 633, in connect
    self._request_authentication()
  File "env/lib/python3.9/site-packages/pymysql/connections.py", line 907, in _request_authentication
    auth_packet = self._read_packet()
  File "env/lib/python3.9/site-packages/pymysql/connections.py", line 725, in _read_packet
    packet.raise_for_error()
  File "env/lib/python3.9/site-packages/pymysql/protocol.py", line 221, in raise_for_error
    err.raise_mysql_exception(self._data)
  File "env/lib/python3.9/site-packages/pymysql/err.py", line 143, in raise_mysql_exception
    raise errorclass(errno, errval)
pymysql.err.OperationalError: (1045, "Access denied for user '_95acf9e769041055'@'localhost' (using password: YES)")

/bin/sh: env/bin/bench: No such file or directory
Backup failed for Site library.test. Database or site_config.json may be corrupted
Traceback (most recent call last):
  File "apps/frappe/frappe/commands/site.py", line 580, in backup
    odb = scheduled_backup(
  File "apps/frappe/frappe/utils/backups.py", line 552, in scheduled_backup
    odb = new_backup(
  File "apps/frappe/frappe/utils/backups.py", line 586, in new_backup
    odb = BackupGenerator(
  File "apps/frappe/frappe/utils/backups.py", line 87, in __init__
    self.setup_backup_tables()
  File "apps/frappe/frappe/utils/backups.py", line 121, in setup_backup_tables
    existing_tables = frappe.db.get_tables()
  File "apps/frappe/frappe/database/database.py", line 879, in get_tables
    table_rows = self.sql("""
  File "apps/frappe/frappe/database/database.py", line 130, in sql
    self.connect()
  File "apps/frappe/frappe/database/database.py", line 75, in connect
    self._conn = self.get_connection()
  File "apps/frappe/frappe/database/mariadb/database.py", line 75, in get_connection
    conn = pymysql.connect(
  File "env/lib/python3.9/site-packages/pymysql/connections.py", line 353, in __init__
    self.connect()
  File "env/lib/python3.9/site-packages/pymysql/connections.py", line 633, in connect
    self._request_authentication()
  File "env/lib/python3.9/site-packages/pymysql/connections.py", line 907, in _request_authentication
    auth_packet = self._read_packet()
  File "env/lib/python3.9/site-packages/pymysql/connections.py", line 725, in _read_packet
    packet.raise_for_error()
  File "env/lib/python3.9/site-packages/pymysql/protocol.py", line 221, in raise_for_error
    err.raise_mysql_exception(self._data)
  File "env/lib/python3.9/site-packages/pymysql/err.py", line 143, in raise_mysql_exception
    raise errorclass(errno, errval)
pymysql.err.OperationalError: (1045, "Access denied for user '_95acf9e769041055'@'localhost' (using password: YES)")

/bin/sh: env/bin/bench: No such file or directory
Backup failed for Site library.test. Database or site_config.json may be corrupted
Traceback (most recent call last):
  File "apps/frappe/frappe/commands/site.py", line 580, in backup
    odb = scheduled_backup(
  File "apps/frappe/frappe/utils/backups.py", line 552, in scheduled_backup
    odb = new_backup(
  File "apps/frappe/frappe/utils/backups.py", line 586, in new_backup
    odb = BackupGenerator(
  File "apps/frappe/frappe/utils/backups.py", line 87, in __init__
    self.setup_backup_tables()
  File "apps/frappe/frappe/utils/backups.py", line 121, in setup_backup_tables
    existing_tables = frappe.db.get_tables()
  File "apps/frappe/frappe/database/database.py", line 879, in get_tables
    table_rows = self.sql("""
  File "apps/frappe/frappe/database/database.py", line 130, in sql
    self.connect()
  File "apps/frappe/frappe/database/database.py", line 75, in connect
    self._conn = self.get_connection()
  File "apps/frappe/frappe/database/mariadb/database.py", line 75, in get_connection
    conn = pymysql.connect(
  File "env/lib/python3.9/site-packages/pymysql/connections.py", line 353, in __init__
    self.connect()
  File "env/lib/python3.9/site-packages/pymysql/connections.py", line 633, in connect
    self._request_authentication()
  File "env/lib/python3.9/site-packages/pymysql/connections.py", line 907, in _request_authentication
    auth_packet = self._read_packet()
  File "env/lib/python3.9/site-packages/pymysql/connections.py", line 725, in _read_packet
    packet.raise_for_error()
  File "env/lib/python3.9/site-packages/pymysql/protocol.py", line 221, in raise_for_error
    err.raise_mysql_exception(self._data)
  File "env/lib/python3.9/site-packages/pymysql/err.py", line 143, in raise_mysql_exception
    raise errorclass(errno, errval)
pymysql.err.OperationalError: (1045, "Access denied for user '_95acf9e769041055'@'localhost' (using password: YES)")

/bin/sh: env/bin/bench: No such file or directory
Backup failed for Site library.test. Database or site_config.json may be corrupted
Traceback (most recent call last):
  File "apps/frappe/frappe/commands/site.py", line 580, in backup
    odb = scheduled_backup(
  File "apps/frappe/frappe/utils/backups.py", line 552, in scheduled_backup
    odb = new_backup(
  File "apps/frappe/frappe/utils/backups.py", line 586, in new_backup
    odb = BackupGenerator(
  File "apps/frappe/frappe/utils/backups.py", line 87, in __init__
    self.setup_backup_tables()
  File "apps/frappe/frappe/utils/backups.py", line 121, in setup_backup_tables
    existing_tables = frappe.db.get_tables()
  File "apps/frappe/frappe/database/database.py", line 879, in get_tables
    table_rows = self.sql("""
  File "apps/frappe/frappe/database/database.py", line 130, in sql
    self.connect()
  File "apps/frappe/frappe/database/database.py", line 75, in connect
    self._conn = self.get_connection()
  File "apps/frappe/frappe/database/mariadb/database.py", line 75, in get_connection
    conn = pymysql.connect(
  File "env/lib/python3.9/site-packages/pymysql/connections.py", line 353, in __init__
    self.connect()
  File "env/lib/python3.9/site-packages/pymysql/connections.py", line 633, in connect
    self._request_authentication()
  File "env/lib/python3.9/site-packages/pymysql/connections.py", line 907, in _request_authentication
    auth_packet = self._read_packet()
  File "env/lib/python3.9/site-packages/pymysql/connections.py", line 725, in _read_packet
    packet.raise_for_error()
  File "env/lib/python3.9/site-packages/pymysql/protocol.py", line 221, in raise_for_error
    err.raise_mysql_exception(self._data)
  File "env/lib/python3.9/site-packages/pymysql/err.py", line 143, in raise_mysql_exception
    raise errorclass(errno, errval)
pymysql.err.OperationalError: (1045, "Access denied for user '_95acf9e769041055'@'localhost' (using password: YES)")

/bin/sh: env/bin/bench: No such file or directory
Backup failed for Site library.test. Database or site_config.json may be corrupted
Traceback (most recent call last):
  File "apps/frappe/frappe/commands/site.py", line 580, in backup
    odb = scheduled_backup(
  File "apps/frappe/frappe/utils/backups.py", line 552, in scheduled_backup
    odb = new_backup(
  File "apps/frappe/frappe/utils/backups.py", line 586, in new_backup
    odb = BackupGenerator(
  File "apps/frappe/frappe/utils/backups.py", line 87, in __init__
    self.setup_backup_tables()
  File "apps/frappe/frappe/utils/backups.py", line 121, in setup_backup_tables
    existing_tables = frappe.db.get_tables()
  File "apps/frappe/frappe/database/database.py", line 879, in get_tables
    table_rows = self.sql("""
  File "apps/frappe/frappe/database/database.py", line 130, in sql
    self.connect()
  File "apps/frappe/frappe/database/database.py", line 75, in connect
    self._conn = self.get_connection()
  File "apps/frappe/frappe/database/mariadb/database.py", line 75, in get_connection
    conn = pymysql.connect(
  File "env/lib/python3.9/site-packages/pymysql/connections.py", line 353, in __init__
    self.connect()
  File "env/lib/python3.9/site-packages/pymysql/connections.py", line 633, in connect
    self._request_authentication()
  File "env/lib/python3.9/site-packages/pymysql/connections.py", line 907, in _request_authentication
    auth_packet = self._read_packet()
  File "env/lib/python3.9/site-packages/pymysql/connections.py", line 725, in _read_packet
    packet.raise_for_error()
  File "env/lib/python3.9/site-packages/pymysql/protocol.py", line 221, in raise_for_error
    err.raise_mysql_exception(self._data)
  File "env/lib/python3.9/site-packages/pymysql/err.py", line 143, in raise_mysql_exception
    raise errorclass(errno, errval)
pymysql.err.OperationalError: (1045, "Access denied for user '_95acf9e769041055'@'localhost' (using password: YES)")

/bin/sh: env/bin/bench: No such file or directory
Backup failed for Site library.test. Database or site_config.json may be corrupted
Traceback (most recent call last):
  File "apps/frappe/frappe/commands/site.py", line 580, in backup
    odb = scheduled_backup(
  File "apps/frappe/frappe/utils/backups.py", line 552, in scheduled_backup
    odb = new_backup(
  File "apps/frappe/frappe/utils/backups.py", line 586, in new_backup
    odb = BackupGenerator(
  File "apps/frappe/frappe/utils/backups.py", line 87, in __init__
    self.setup_backup_tables()
  File "apps/frappe/frappe/utils/backups.py", line 121, in setup_backup_tables
    existing_tables = frappe.db.get_tables()
  File "apps/frappe/frappe/database/database.py", line 879, in get_tables
    table_rows = self.sql("""
  File "apps/frappe/frappe/database/database.py", line 130, in sql
    self.connect()
  File "apps/frappe/frappe/database/database.py", line 75, in connect
    self._conn = self.get_connection()
  File "apps/frappe/frappe/database/mariadb/database.py", line 75, in get_connection
    conn = pymysql.connect(
  File "env/lib/python3.9/site-packages/pymysql/connections.py", line 353, in __init__
    self.connect()
  File "env/lib/python3.9/site-packages/pymysql/connections.py", line 633, in connect
    self._request_authentication()
  File "env/lib/python3.9/site-packages/pymysql/connections.py", line 907, in _request_authentication
    auth_packet = self._read_packet()
  File "env/lib/python3.9/site-packages/pymysql/connections.py", line 725, in _read_packet
    packet.raise_for_error()
  File "env/lib/python3.9/site-packages/pymysql/protocol.py", line 221, in raise_for_error
    err.raise_mysql_exception(self._data)
  File "env/lib/python3.9/site-packages/pymysql/err.py", line 143, in raise_mysql_exception
    raise errorclass(errno, errval)
pymysql.err.OperationalError: (1045, "Access denied for user '_95acf9e769041055'@'localhost' (using password: YES)")

/bin/sh: env/bin/bench: No such file or directory
Backup failed for Site library.test. Database or site_config.json may be corrupted
Traceback (most recent call last):
  File "apps/frappe/frappe/commands/site.py", line 580, in backup
    odb = scheduled_backup(
  File "apps/frappe/frappe/utils/backups.py", line 552, in scheduled_backup
    odb = new_backup(
  File "apps/frappe/frappe/utils/backups.py", line 586, in new_backup
    odb = BackupGenerator(
  File "apps/frappe/frappe/utils/backups.py", line 87, in __init__
    self.setup_backup_tables()
  File "apps/frappe/frappe/utils/backups.py", line 121, in setup_backup_tables
    existing_tables = frappe.db.get_tables()
  File "apps/frappe/frappe/database/database.py", line 879, in get_tables
    table_rows = self.sql("""
  File "apps/frappe/frappe/database/database.py", line 130, in sql
    self.connect()
  File "apps/frappe/frappe/database/database.py", line 75, in connect
    self._conn = self.get_connection()
  File "apps/frappe/frappe/database/mariadb/database.py", line 75, in get_connection
    conn = pymysql.connect(
  File "env/lib/python3.9/site-packages/pymysql/connections.py", line 353, in __init__
    self.connect()
  File "env/lib/python3.9/site-packages/pymysql/connections.py", line 633, in connect
    self._request_authentication()
  File "env/lib/python3.9/site-packages/pymysql/connections.py", line 907, in _request_authentication
    auth_packet = self._read_packet()
  File "env/lib/python3.9/site-packages/pymysql/connections.py", line 725, in _read_packet
    packet.raise_for_error()
  File "env/lib/python3.9/site-packages/pymysql/protocol.py", line 221, in raise_for_error
    err.raise_mysql_exception(self._data)
  File "env/lib/python3.9/site-packages/pymysql/err.py", line 143, in raise_mysql_exception
    raise errorclass(errno, errval)
pymysql.err.OperationalError: (1045, "Access denied for user '_95acf9e769041055'@'localhost' (using password: YES)")

/bin/sh: env/bin/bench: No such file or directory
Backup failed for Site library.test. Database or site_config.json may be corrupted
Traceback (most recent call last):
  File "apps/frappe/frappe/commands/site.py", line 580, in backup
    odb = scheduled_backup(
  File "apps/frappe/frappe/utils/backups.py", line 552, in scheduled_backup
    odb = new_backup(
  File "apps/frappe/frappe/utils/backups.py", line 586, in new_backup
    odb = BackupGenerator(
  File "apps/frappe/frappe/utils/backups.py", line 87, in __init__
    self.setup_backup_tables()
  File "apps/frappe/frappe/utils/backups.py", line 121, in setup_backup_tables
    existing_tables = frappe.db.get_tables()
  File "apps/frappe/frappe/database/database.py", line 879, in get_tables
    table_rows = self.sql("""
  File "apps/frappe/frappe/database/database.py", line 130, in sql
    self.connect()
  File "apps/frappe/frappe/database/database.py", line 75, in connect
    self._conn = self.get_connection()
  File "apps/frappe/frappe/database/mariadb/database.py", line 75, in get_connection
    conn = pymysql.connect(
  File "env/lib/python3.9/site-packages/pymysql/connections.py", line 353, in __init__
    self.connect()
  File "env/lib/python3.9/site-packages/pymysql/connections.py", line 633, in connect
    self._request_authentication()
  File "env/lib/python3.9/site-packages/pymysql/connections.py", line 907, in _request_authentication
    auth_packet = self._read_packet()
  File "env/lib/python3.9/site-packages/pymysql/connections.py", line 725, in _read_packet
    packet.raise_for_error()
  File "env/lib/python3.9/site-packages/pymysql/protocol.py", line 221, in raise_for_error
    err.raise_mysql_exception(self._data)
  File "env/lib/python3.9/site-packages/pymysql/err.py", line 143, in raise_mysql_exception
    raise errorclass(errno, errval)
pymysql.err.OperationalError: (1045, "Access denied for user '_95acf9e769041055'@'localhost' (using password: YES)")

/bin/sh: env/bin/bench: No such file or directory
Backup failed for Site library.test. Database or site_config.json may be corrupted
Traceback (most recent call last):
  File "apps/frappe/frappe/commands/site.py", line 580, in backup
    odb = scheduled_backup(
  File "apps/frappe/frappe/utils/backups.py", line 552, in scheduled_backup
    odb = new_backup(
  File "apps/frappe/frappe/utils/backups.py", line 586, in new_backup
    odb = BackupGenerator(
  File "apps/frappe/frappe/utils/backups.py", line 87, in __init__
    self.setup_backup_tables()
  File "apps/frappe/frappe/utils/backups.py", line 121, in setup_backup_tables
    existing_tables = frappe.db.get_tables()
  File "apps/frappe/frappe/database/database.py", line 879, in get_tables
    table_rows = self.sql("""
  File "apps/frappe/frappe/database/database.py", line 130, in sql
    self.connect()
  File "apps/frappe/frappe/database/database.py", line 75, in connect
    self._conn = self.get_connection()
  File "apps/frappe/frappe/database/mariadb/database.py", line 75, in get_connection
    conn = pymysql.connect(
  File "env/lib/python3.9/site-packages/pymysql/connections.py", line 353, in __init__
    self.connect()
  File "env/lib/python3.9/site-packages/pymysql/connections.py", line 633, in connect
    self._request_authentication()
  File "env/lib/python3.9/site-packages/pymysql/connections.py", line 907, in _request_authentication
    auth_packet = self._read_packet()
  File "env/lib/python3.9/site-packages/pymysql/connections.py", line 725, in _read_packet
    packet.raise_for_error()
  File "env/lib/python3.9/site-packages/pymysql/protocol.py", line 221, in raise_for_error
    err.raise_mysql_exception(self._data)
  File "env/lib/python3.9/site-packages/pymysql/err.py", line 143, in raise_mysql_exception
    raise errorclass(errno, errval)
pymysql.err.OperationalError: (1045, "Access denied for user '_95acf9e769041055'@'localhost' (using password: YES)")

/bin/sh: env/bin/bench: No such file or directory
Backup failed for Site library.test. Database or site_config.json may be corrupted
Traceback (most recent call last):
  File "apps/frappe/frappe/commands/site.py", line 580, in backup
    odb = scheduled_backup(
  File "apps/frappe/frappe/utils/backups.py", line 552, in scheduled_backup
    odb = new_backup(
  File "apps/frappe/frappe/utils/backups.py", line 586, in new_backup
    odb = BackupGenerator(
  File "apps/frappe/frappe/utils/backups.py", line 87, in __init__
    self.setup_backup_tables()
  File "apps/frappe/frappe/utils/backups.py", line 121, in setup_backup_tables
    existing_tables = frappe.db.get_tables()
  File "apps/frappe/frappe/database/database.py", line 879, in get_tables
    table_rows = self.sql("""
  File "apps/frappe/frappe/database/database.py", line 130, in sql
    self.connect()
  File "apps/frappe/frappe/database/database.py", line 75, in connect
    self._conn = self.get_connection()
  File "apps/frappe/frappe/database/mariadb/database.py", line 75, in get_connection
    conn = pymysql.connect(
  File "env/lib/python3.9/site-packages/pymysql/connections.py", line 353, in __init__
    self.connect()
  File "env/lib/python3.9/site-packages/pymysql/connections.py", line 633, in connect
    self._request_authentication()
  File "env/lib/python3.9/site-packages/pymysql/connections.py", line 907, in _request_authentication
    auth_packet = self._read_packet()
  File "env/lib/python3.9/site-packages/pymysql/connections.py", line 725, in _read_packet
    packet.raise_for_error()
  File "env/lib/python3.9/site-packages/pymysql/protocol.py", line 221, in raise_for_error
    err.raise_mysql_exception(self._data)
  File "env/lib/python3.9/site-packages/pymysql/err.py", line 143, in raise_mysql_exception
    raise errorclass(errno, errval)
pymysql.err.OperationalError: (1045, "Access denied for user '_95acf9e769041055'@'localhost' (using password: YES)")

/bin/sh: env/bin/bench: No such file or directory
Backup failed for Site library.test. Database or site_config.json may be corrupted
Traceback (most recent call last):
  File "apps/frappe/frappe/commands/site.py", line 580, in backup
    odb = scheduled_backup(
  File "apps/frappe/frappe/utils/backups.py", line 552, in scheduled_backup
    odb = new_backup(
  File "apps/frappe/frappe/utils/backups.py", line 586, in new_backup
    odb = BackupGenerator(
  File "apps/frappe/frappe/utils/backups.py", line 87, in __init__
    self.setup_backup_tables()
  File "apps/frappe/frappe/utils/backups.py", line 121, in setup_backup_tables
    existing_tables = frappe.db.get_tables()
  File "apps/frappe/frappe/database/database.py", line 879, in get_tables
    table_rows = self.sql("""
  File "apps/frappe/frappe/database/database.py", line 130, in sql
    self.connect()
  File "apps/frappe/frappe/database/database.py", line 75, in connect
    self._conn = self.get_connection()
  File "apps/frappe/frappe/database/mariadb/database.py", line 75, in get_connection
    conn = pymysql.connect(
  File "env/lib/python3.9/site-packages/pymysql/connections.py", line 353, in __init__
    self.connect()
  File "env/lib/python3.9/site-packages/pymysql/connections.py", line 633, in connect
    self._request_authentication()
  File "env/lib/python3.9/site-packages/pymysql/connections.py", line 907, in _request_authentication
    auth_packet = self._read_packet()
  File "env/lib/python3.9/site-packages/pymysql/connections.py", line 725, in _read_packet
    packet.raise_for_error()
  File "env/lib/python3.9/site-packages/pymysql/protocol.py", line 221, in raise_for_error
    err.raise_mysql_exception(self._data)
  File "env/lib/python3.9/site-packages/pymysql/err.py", line 143, in raise_mysql_exception
    raise errorclass(errno, errval)
pymysql.err.OperationalError: (1045, "Access denied for user '_95acf9e769041055'@'localhost' (using password: YES)")

/bin/sh: env/bin/bench: No such file or directory
Backup failed for Site library.test. Database or site_config.json may be corrupted
Traceback (most recent call last):
  File "apps/frappe/frappe/commands/site.py", line 580, in backup
    odb = scheduled_backup(
  File "apps/frappe/frappe/utils/backups.py", line 552, in scheduled_backup
    odb = new_backup(
  File "apps/frappe/frappe/utils/backups.py", line 586, in new_backup
    odb = BackupGenerator(
  File "apps/frappe/frappe/utils/backups.py", line 87, in __init__
    self.setup_backup_tables()
  File "apps/frappe/frappe/utils/backups.py", line 121, in setup_backup_tables
    existing_tables = frappe.db.get_tables()
  File "apps/frappe/frappe/database/database.py", line 879, in get_tables
    table_rows = self.sql("""
  File "apps/frappe/frappe/database/database.py", line 130, in sql
    self.connect()
  File "apps/frappe/frappe/database/database.py", line 75, in connect
    self._conn = self.get_connection()
  File "apps/frappe/frappe/database/mariadb/database.py", line 75, in get_connection
    conn = pymysql.connect(
  File "env/lib/python3.9/site-packages/pymysql/connections.py", line 353, in __init__
    self.connect()
  File "env/lib/python3.9/site-packages/pymysql/connections.py", line 633, in connect
    self._request_authentication()
  File "env/lib/python3.9/site-packages/pymysql/connections.py", line 907, in _request_authentication
    auth_packet = self._read_packet()
  File "env/lib/python3.9/site-packages/pymysql/connections.py", line 725, in _read_packet
    packet.raise_for_error()
  File "env/lib/python3.9/site-packages/pymysql/protocol.py", line 221, in raise_for_error
    err.raise_mysql_exception(self._data)
  File "env/lib/python3.9/site-packages/pymysql/err.py", line 143, in raise_mysql_exception
    raise errorclass(errno, errval)
pymysql.err.OperationalError: (1045, "Access denied for user '_95acf9e769041055'@'localhost' (using password: YES)")

/bin/sh: env/bin/bench: No such file or directory
Backup failed for Site library.test. Database or site_config.json may be corrupted
Traceback (most recent call last):
  File "apps/frappe/frappe/commands/site.py", line 580, in backup
    odb = scheduled_backup(
  File "apps/frappe/frappe/utils/backups.py", line 552, in scheduled_backup
    odb = new_backup(
  File "apps/frappe/frappe/utils/backups.py", line 586, in new_backup
    odb = BackupGenerator(
  File "apps/frappe/frappe/utils/backups.py", line 87, in __init__
    self.setup_backup_tables()
  File "apps/frappe/frappe/utils/backups.py", line 121, in setup_backup_tables
    existing_tables = frappe.db.get_tables()
  File "apps/frappe/frappe/database/database.py", line 879, in get_tables
    table_rows = self.sql("""
  File "apps/frappe/frappe/database/database.py", line 130, in sql
    self.connect()
  File "apps/frappe/frappe/database/database.py", line 75, in connect
    self._conn = self.get_connection()
  File "apps/frappe/frappe/database/mariadb/database.py", line 75, in get_connection
    conn = pymysql.connect(
  File "env/lib/python3.9/site-packages/pymysql/connections.py", line 353, in __init__
    self.connect()
  File "env/lib/python3.9/site-packages/pymysql/connections.py", line 633, in connect
    self._request_authentication()
  File "env/lib/python3.9/site-packages/pymysql/connections.py", line 907, in _request_authentication
    auth_packet = self._read_packet()
  File "env/lib/python3.9/site-packages/pymysql/connections.py", line 725, in _read_packet
    packet.raise_for_error()
  File "env/lib/python3.9/site-packages/pymysql/protocol.py", line 221, in raise_for_error
    err.raise_mysql_exception(self._data)
  File "env/lib/python3.9/site-packages/pymysql/err.py", line 143, in raise_mysql_exception
    raise errorclass(errno, errval)
pymysql.err.OperationalError: (1045, "Access denied for user '_95acf9e769041055'@'localhost' (using password: YES)")

/bin/sh: env/bin/bench: No such file or directory
Backup failed for Site library.test. Database or site_config.json may be corrupted
Traceback (most recent call last):
  File "apps/frappe/frappe/commands/site.py", line 580, in backup
    odb = scheduled_backup(
  File "apps/frappe/frappe/utils/backups.py", line 552, in scheduled_backup
    odb = new_backup(
  File "apps/frappe/frappe/utils/backups.py", line 586, in new_backup
    odb = BackupGenerator(
  File "apps/frappe/frappe/utils/backups.py", line 87, in __init__
    self.setup_backup_tables()
  File "apps/frappe/frappe/utils/backups.py", line 121, in setup_backup_tables
    existing_tables = frappe.db.get_tables()
  File "apps/frappe/frappe/database/database.py", line 879, in get_tables
    table_rows = self.sql("""
  File "apps/frappe/frappe/database/database.py", line 130, in sql
    self.connect()
  File "apps/frappe/frappe/database/database.py", line 75, in connect
    self._conn = self.get_connection()
  File "apps/frappe/frappe/database/mariadb/database.py", line 75, in get_connection
    conn = pymysql.connect(
  File "env/lib/python3.9/site-packages/pymysql/connections.py", line 353, in __init__
    self.connect()
  File "env/lib/python3.9/site-packages/pymysql/connections.py", line 633, in connect
    self._request_authentication()
  File "env/lib/python3.9/site-packages/pymysql/connections.py", line 907, in _request_authentication
    auth_packet = self._read_packet()
  File "env/lib/python3.9/site-packages/pymysql/connections.py", line 725, in _read_packet
    packet.raise_for_error()
  File "env/lib/python3.9/site-packages/pymysql/protocol.py", line 221, in raise_for_error
    err.raise_mysql_exception(self._data)
  File "env/lib/python3.9/site-packages/pymysql/err.py", line 143, in raise_mysql_exception
    raise errorclass(errno, errval)
pymysql.err.OperationalError: (1045, "Access denied for user '_95acf9e769041055'@'localhost' (using password: YES)")

/bin/sh: env/bin/bench: No such file or directory
Backup failed for Site library.test. Database or site_config.json may be corrupted
Traceback (most recent call last):
  File "apps/frappe/frappe/commands/site.py", line 580, in backup
    odb = scheduled_backup(
  File "apps/frappe/frappe/utils/backups.py", line 552, in scheduled_backup
    odb = new_backup(
  File "apps/frappe/frappe/utils/backups.py", line 586, in new_backup
    odb = BackupGenerator(
  File "apps/frappe/frappe/utils/backups.py", line 87, in __init__
    self.setup_backup_tables()
  File "apps/frappe/frappe/utils/backups.py", line 121, in setup_backup_tables
    existing_tables = frappe.db.get_tables()
  File "apps/frappe/frappe/database/database.py", line 879, in get_tables
    table_rows = self.sql("""
  File "apps/frappe/frappe/database/database.py", line 130, in sql
    self.connect()
  File "apps/frappe/frappe/database/database.py", line 75, in connect
    self._conn = self.get_connection()
  File "apps/frappe/frappe/database/mariadb/database.py", line 75, in get_connection
    conn = pymysql.connect(
  File "env/lib/python3.9/site-packages/pymysql/connections.py", line 353, in __init__
    self.connect()
  File "env/lib/python3.9/site-packages/pymysql/connections.py", line 633, in connect
    self._request_authentication()
  File "env/lib/python3.9/site-packages/pymysql/connections.py", line 907, in _request_authentication
    auth_packet = self._read_packet()
  File "env/lib/python3.9/site-packages/pymysql/connections.py", line 725, in _read_packet
    packet.raise_for_error()
  File "env/lib/python3.9/site-packages/pymysql/protocol.py", line 221, in raise_for_error
    err.raise_mysql_exception(self._data)
  File "env/lib/python3.9/site-packages/pymysql/err.py", line 143, in raise_mysql_exception
    raise errorclass(errno, errval)
pymysql.err.OperationalError: (1045, "Access denied for user '_95acf9e769041055'@'localhost' (using password: YES)")

/bin/sh: env/bin/bench: No such file or directory
Backup failed for Site library.test. Database or site_config.json may be corrupted
Traceback (most recent call last):
  File "apps/frappe/frappe/commands/site.py", line 580, in backup
    odb = scheduled_backup(
  File "apps/frappe/frappe/utils/backups.py", line 552, in scheduled_backup
    odb = new_backup(
  File "apps/frappe/frappe/utils/backups.py", line 586, in new_backup
    odb = BackupGenerator(
  File "apps/frappe/frappe/utils/backups.py", line 87, in __init__
    self.setup_backup_tables()
  File "apps/frappe/frappe/utils/backups.py", line 121, in setup_backup_tables
    existing_tables = frappe.db.get_tables()
  File "apps/frappe/frappe/database/database.py", line 879, in get_tables
    table_rows = self.sql("""
  File "apps/frappe/frappe/database/database.py", line 130, in sql
    self.connect()
  File "apps/frappe/frappe/database/database.py", line 75, in connect
    self._conn = self.get_connection()
  File "apps/frappe/frappe/database/mariadb/database.py", line 75, in get_connection
    conn = pymysql.connect(
  File "env/lib/python3.9/site-packages/pymysql/connections.py", line 353, in __init__
    self.connect()
  File "env/lib/python3.9/site-packages/pymysql/connections.py", line 633, in connect
    self._request_authentication()
  File "env/lib/python3.9/site-packages/pymysql/connections.py", line 907, in _request_authentication
    auth_packet = self._read_packet()
  File "env/lib/python3.9/site-packages/pymysql/connections.py", line 725, in _read_packet
    packet.raise_for_error()
  File "env/lib/python3.9/site-packages/pymysql/protocol.py", line 221, in raise_for_error
    err.raise_mysql_exception(self._data)
  File "env/lib/python3.9/site-packages/pymysql/err.py", line 143, in raise_mysql_exception
    raise errorclass(errno, errval)
pymysql.err.OperationalError: (1045, "Access denied for user '_95acf9e769041055'@'localhost' (using password: YES)")

/bin/sh: env/bin/bench: No such file or directory
Backup failed for Site library.test. Database or site_config.json may be corrupted
Traceback (most recent call last):
  File "apps/frappe/frappe/commands/site.py", line 580, in backup
    odb = scheduled_backup(
  File "apps/frappe/frappe/utils/backups.py", line 552, in scheduled_backup
    odb = new_backup(
  File "apps/frappe/frappe/utils/backups.py", line 586, in new_backup
    odb = BackupGenerator(
  File "apps/frappe/frappe/utils/backups.py", line 87, in __init__
    self.setup_backup_tables()
  File "apps/frappe/frappe/utils/backups.py", line 121, in setup_backup_tables
    existing_tables = frappe.db.get_tables()
  File "apps/frappe/frappe/database/database.py", line 879, in get_tables
    table_rows = self.sql("""
  File "apps/frappe/frappe/database/database.py", line 130, in sql
    self.connect()
  File "apps/frappe/frappe/database/database.py", line 75, in connect
    self._conn = self.get_connection()
  File "apps/frappe/frappe/database/mariadb/database.py", line 75, in get_connection
    conn = pymysql.connect(
  File "env/lib/python3.9/site-packages/pymysql/connections.py", line 353, in __init__
    self.connect()
  File "env/lib/python3.9/site-packages/pymysql/connections.py", line 633, in connect
    self._request_authentication()
  File "env/lib/python3.9/site-packages/pymysql/connections.py", line 907, in _request_authentication
    auth_packet = self._read_packet()
  File "env/lib/python3.9/site-packages/pymysql/connections.py", line 725, in _read_packet
    packet.raise_for_error()
  File "env/lib/python3.9/site-packages/pymysql/protocol.py", line 221, in raise_for_error
    err.raise_mysql_exception(self._data)
  File "env/lib/python3.9/site-packages/pymysql/err.py", line 143, in raise_mysql_exception
    raise errorclass(errno, errval)
pymysql.err.OperationalError: (1045, "Access denied for user '_95acf9e769041055'@'localhost' (using password: YES)")

/bin/sh: env/bin/bench: No such file or directory
Backup failed for Site library.test. Database or site_config.json may be corrupted
Traceback (most recent call last):
  File "apps/frappe/frappe/commands/site.py", line 580, in backup
    odb = scheduled_backup(
  File "apps/frappe/frappe/utils/backups.py", line 552, in scheduled_backup
    odb = new_backup(
  File "apps/frappe/frappe/utils/backups.py", line 586, in new_backup
    odb = BackupGenerator(
  File "apps/frappe/frappe/utils/backups.py", line 87, in __init__
    self.setup_backup_tables()
  File "apps/frappe/frappe/utils/backups.py", line 121, in setup_backup_tables
    existing_tables = frappe.db.get_tables()
  File "apps/frappe/frappe/database/database.py", line 879, in get_tables
    table_rows = self.sql("""
  File "apps/frappe/frappe/database/database.py", line 130, in sql
    self.connect()
  File "apps/frappe/frappe/database/database.py", line 75, in connect
    self._conn = self.get_connection()
  File "apps/frappe/frappe/database/mariadb/database.py", line 75, in get_connection
    conn = pymysql.connect(
  File "env/lib/python3.9/site-packages/pymysql/connections.py", line 353, in __init__
    self.connect()
  File "env/lib/python3.9/site-packages/pymysql/connections.py", line 633, in connect
    self._request_authentication()
  File "env/lib/python3.9/site-packages/pymysql/connections.py", line 907, in _request_authentication
    auth_packet = self._read_packet()
  File "env/lib/python3.9/site-packages/pymysql/connections.py", line 725, in _read_packet
    packet.raise_for_error()
  File "env/lib/python3.9/site-packages/pymysql/protocol.py", line 221, in raise_for_error
    err.raise_mysql_exception(self._data)
  File "env/lib/python3.9/site-packages/pymysql/err.py", line 143, in raise_mysql_exception
    raise errorclass(errno, errval)
pymysql.err.OperationalError: (1045, "Access denied for user '_95acf9e769041055'@'localhost' (using password: YES)")

/bin/sh: env/bin/bench: No such file or directory
Backup failed for Site library.test. Database or site_config.json may be corrupted
Traceback (most recent call last):
  File "apps/frappe/frappe/commands/site.py", line 580, in backup
    odb = scheduled_backup(
  File "apps/frappe/frappe/utils/backups.py", line 552, in scheduled_backup
    odb = new_backup(
  File "apps/frappe/frappe/utils/backups.py", line 586, in new_backup
    odb = BackupGenerator(
  File "apps/frappe/frappe/utils/backups.py", line 87, in __init__
    self.setup_backup_tables()
  File "apps/frappe/frappe/utils/backups.py", line 121, in setup_backup_tables
    existing_tables = frappe.db.get_tables()
  File "apps/frappe/frappe/database/database.py", line 879, in get_tables
    table_rows = self.sql("""
  File "apps/frappe/frappe/database/database.py", line 130, in sql
    self.connect()
  File "apps/frappe/frappe/database/database.py", line 75, in connect
    self._conn = self.get_connection()
  File "apps/frappe/frappe/database/mariadb/database.py", line 75, in get_connection
    conn = pymysql.connect(
  File "env/lib/python3.9/site-packages/pymysql/connections.py", line 353, in __init__
    self.connect()
  File "env/lib/python3.9/site-packages/pymysql/connections.py", line 633, in connect
    self._request_authentication()
  File "env/lib/python3.9/site-packages/pymysql/connections.py", line 907, in _request_authentication
    auth_packet = self._read_packet()
  File "env/lib/python3.9/site-packages/pymysql/connections.py", line 725, in _read_packet
    packet.raise_for_error()
  File "env/lib/python3.9/site-packages/pymysql/protocol.py", line 221, in raise_for_error
    err.raise_mysql_exception(self._data)
  File "env/lib/python3.9/site-packages/pymysql/err.py", line 143, in raise_mysql_exception
    raise errorclass(errno, errval)
pymysql.err.OperationalError: (1045, "Access denied for user '_95acf9e769041055'@'localhost' (using password: YES)")

/bin/sh: env/bin/bench: No such file or directory
Backup failed for Site library.test. Database or site_config.json may be corrupted
Traceback (most recent call last):
  File "apps/frappe/frappe/commands/site.py", line 580, in backup
    odb = scheduled_backup(
  File "apps/frappe/frappe/utils/backups.py", line 552, in scheduled_backup
    odb = new_backup(
  File "apps/frappe/frappe/utils/backups.py", line 586, in new_backup
    odb = BackupGenerator(
  File "apps/frappe/frappe/utils/backups.py", line 87, in __init__
    self.setup_backup_tables()
  File "apps/frappe/frappe/utils/backups.py", line 121, in setup_backup_tables
    existing_tables = frappe.db.get_tables()
  File "apps/frappe/frappe/database/database.py", line 879, in get_tables
    table_rows = self.sql("""
  File "apps/frappe/frappe/database/database.py", line 130, in sql
    self.connect()
  File "apps/frappe/frappe/database/database.py", line 75, in connect
    self._conn = self.get_connection()
  File "apps/frappe/frappe/database/mariadb/database.py", line 75, in get_connection
    conn = pymysql.connect(
  File "env/lib/python3.9/site-packages/pymysql/connections.py", line 353, in __init__
    self.connect()
  File "env/lib/python3.9/site-packages/pymysql/connections.py", line 633, in connect
    self._request_authentication()
  File "env/lib/python3.9/site-packages/pymysql/connections.py", line 907, in _request_authentication
    auth_packet = self._read_packet()
  File "env/lib/python3.9/site-packages/pymysql/connections.py", line 725, in _read_packet
    packet.raise_for_error()
  File "env/lib/python3.9/site-packages/pymysql/protocol.py", line 221, in raise_for_error
    err.raise_mysql_exception(self._data)
  File "env/lib/python3.9/site-packages/pymysql/err.py", line 143, in raise_mysql_exception
    raise errorclass(errno, errval)
pymysql.err.OperationalError: (1045, "Access denied for user '_95acf9e769041055'@'localhost' (using password: YES)")

/bin/sh: env/bin/bench: No such file or directory
Backup failed for Site library.test. Database or site_config.json may be corrupted
Traceback (most recent call last):
  File "apps/frappe/frappe/commands/site.py", line 580, in backup
    odb = scheduled_backup(
  File "apps/frappe/frappe/utils/backups.py", line 552, in scheduled_backup
    odb = new_backup(
  File "apps/frappe/frappe/utils/backups.py", line 586, in new_backup
    odb = BackupGenerator(
  File "apps/frappe/frappe/utils/backups.py", line 87, in __init__
    self.setup_backup_tables()
  File "apps/frappe/frappe/utils/backups.py", line 121, in setup_backup_tables
    existing_tables = frappe.db.get_tables()
  File "apps/frappe/frappe/database/database.py", line 879, in get_tables
    table_rows = self.sql("""
  File "apps/frappe/frappe/database/database.py", line 130, in sql
    self.connect()
  File "apps/frappe/frappe/database/database.py", line 75, in connect
    self._conn = self.get_connection()
  File "apps/frappe/frappe/database/mariadb/database.py", line 75, in get_connection
    conn = pymysql.connect(
  File "env/lib/python3.9/site-packages/pymysql/connections.py", line 353, in __init__
    self.connect()
  File "env/lib/python3.9/site-packages/pymysql/connections.py", line 633, in connect
    self._request_authentication()
  File "env/lib/python3.9/site-packages/pymysql/connections.py", line 907, in _request_authentication
    auth_packet = self._read_packet()
  File "env/lib/python3.9/site-packages/pymysql/connections.py", line 725, in _read_packet
    packet.raise_for_error()
  File "env/lib/python3.9/site-packages/pymysql/protocol.py", line 221, in raise_for_error
    err.raise_mysql_exception(self._data)
  File "env/lib/python3.9/site-packages/pymysql/err.py", line 143, in raise_mysql_exception
    raise errorclass(errno, errval)
pymysql.err.OperationalError: (1045, "Access denied for user '_95acf9e769041055'@'localhost' (using password: YES)")

/bin/sh: env/bin/bench: No such file or directory
Backup failed for Site library.test. Database or site_config.json may be corrupted
Traceback (most recent call last):
  File "apps/frappe/frappe/commands/site.py", line 580, in backup
    odb = scheduled_backup(
  File "apps/frappe/frappe/utils/backups.py", line 552, in scheduled_backup
    odb = new_backup(
  File "apps/frappe/frappe/utils/backups.py", line 586, in new_backup
    odb = BackupGenerator(
  File "apps/frappe/frappe/utils/backups.py", line 87, in __init__
    self.setup_backup_tables()
  File "apps/frappe/frappe/utils/backups.py", line 121, in setup_backup_tables
    existing_tables = frappe.db.get_tables()
  File "apps/frappe/frappe/database/database.py", line 879, in get_tables
    table_rows = self.sql("""
  File "apps/frappe/frappe/database/database.py", line 130, in sql
    self.connect()
  File "apps/frappe/frappe/database/database.py", line 75, in connect
    self._conn = self.get_connection()
  File "apps/frappe/frappe/database/mariadb/database.py", line 75, in get_connection
    conn = pymysql.connect(
  File "env/lib/python3.9/site-packages/pymysql/connections.py", line 353, in __init__
    self.connect()
  File "env/lib/python3.9/site-packages/pymysql/connections.py", line 633, in connect
    self._request_authentication()
  File "env/lib/python3.9/site-packages/pymysql/connections.py", line 907, in _request_authentication
    auth_packet = self._read_packet()
  File "env/lib/python3.9/site-packages/pymysql/connections.py", line 725, in _read_packet
    packet.raise_for_error()
  File "env/lib/python3.9/site-packages/pymysql/protocol.py", line 221, in raise_for_error
    err.raise_mysql_exception(self._data)
  File "env/lib/python3.9/site-packages/pymysql/err.py", line 143, in raise_mysql_exception
    raise errorclass(errno, errval)
pymysql.err.OperationalError: (1045, "Access denied for user '_95acf9e769041055'@'localhost' (using password: YES)")

/bin/sh: env/bin/bench: No such file or directory
Backup failed for Site library.test. Database or site_config.json may be corrupted
Traceback (most recent call last):
  File "apps/frappe/frappe/commands/site.py", line 580, in backup
    odb = scheduled_backup(
  File "apps/frappe/frappe/utils/backups.py", line 552, in scheduled_backup
    odb = new_backup(
  File "apps/frappe/frappe/utils/backups.py", line 586, in new_backup
    odb = BackupGenerator(
  File "apps/frappe/frappe/utils/backups.py", line 87, in __init__
    self.setup_backup_tables()
  File "apps/frappe/frappe/utils/backups.py", line 121, in setup_backup_tables
    existing_tables = frappe.db.get_tables()
  File "apps/frappe/frappe/database/database.py", line 879, in get_tables
    table_rows = self.sql("""
  File "apps/frappe/frappe/database/database.py", line 130, in sql
    self.connect()
  File "apps/frappe/frappe/database/database.py", line 75, in connect
    self._conn = self.get_connection()
  File "apps/frappe/frappe/database/mariadb/database.py", line 75, in get_connection
    conn = pymysql.connect(
  File "env/lib/python3.9/site-packages/pymysql/connections.py", line 353, in __init__
    self.connect()
  File "env/lib/python3.9/site-packages/pymysql/connections.py", line 633, in connect
    self._request_authentication()
  File "env/lib/python3.9/site-packages/pymysql/connections.py", line 907, in _request_authentication
    auth_packet = self._read_packet()
  File "env/lib/python3.9/site-packages/pymysql/connections.py", line 725, in _read_packet
    packet.raise_for_error()
  File "env/lib/python3.9/site-packages/pymysql/protocol.py", line 221, in raise_for_error
    err.raise_mysql_exception(self._data)
  File "env/lib/python3.9/site-packages/pymysql/err.py", line 143, in raise_mysql_exception
    raise errorclass(errno, errval)
pymysql.err.OperationalError: (1045, "Access denied for user '_95acf9e769041055'@'localhost' (using password: YES)")

/bin/sh: env/bin/bench: No such file or directory
Backup failed for Site library.test. Database or site_config.json may be corrupted
Traceback (most recent call last):
  File "apps/frappe/frappe/commands/site.py", line 580, in backup
    odb = scheduled_backup(
  File "apps/frappe/frappe/utils/backups.py", line 552, in scheduled_backup
    odb = new_backup(
  File "apps/frappe/frappe/utils/backups.py", line 586, in new_backup
    odb = BackupGenerator(
  File "apps/frappe/frappe/utils/backups.py", line 87, in __init__
    self.setup_backup_tables()
  File "apps/frappe/frappe/utils/backups.py", line 121, in setup_backup_tables
    existing_tables = frappe.db.get_tables()
  File "apps/frappe/frappe/database/database.py", line 879, in get_tables
    table_rows = self.sql("""
  File "apps/frappe/frappe/database/database.py", line 130, in sql
    self.connect()
  File "apps/frappe/frappe/database/database.py", line 75, in connect
    self._conn = self.get_connection()
  File "apps/frappe/frappe/database/mariadb/database.py", line 75, in get_connection
    conn = pymysql.connect(
  File "env/lib/python3.9/site-packages/pymysql/connections.py", line 353, in __init__
    self.connect()
  File "env/lib/python3.9/site-packages/pymysql/connections.py", line 633, in connect
    self._request_authentication()
  File "env/lib/python3.9/site-packages/pymysql/connections.py", line 907, in _request_authentication
    auth_packet = self._read_packet()
  File "env/lib/python3.9/site-packages/pymysql/connections.py", line 725, in _read_packet
    packet.raise_for_error()
  File "env/lib/python3.9/site-packages/pymysql/protocol.py", line 221, in raise_for_error
    err.raise_mysql_exception(self._data)
  File "env/lib/python3.9/site-packages/pymysql/err.py", line 143, in raise_mysql_exception
    raise errorclass(errno, errval)
pymysql.err.OperationalError: (1045, "Access denied for user '_95acf9e769041055'@'localhost' (using password: YES)")

/bin/sh: env/bin/bench: No such file or directory
Backup failed for Site library.test. Database or site_config.json may be corrupted
Traceback (most recent call last):
  File "apps/frappe/frappe/commands/site.py", line 580, in backup
    odb = scheduled_backup(
  File "apps/frappe/frappe/utils/backups.py", line 552, in scheduled_backup
    odb = new_backup(
  File "apps/frappe/frappe/utils/backups.py", line 586, in new_backup
    odb = BackupGenerator(
  File "apps/frappe/frappe/utils/backups.py", line 87, in __init__
    self.setup_backup_tables()
  File "apps/frappe/frappe/utils/backups.py", line 121, in setup_backup_tables
    existing_tables = frappe.db.get_tables()
  File "apps/frappe/frappe/database/database.py", line 879, in get_tables
    table_rows = self.sql("""
  File "apps/frappe/frappe/database/database.py", line 130, in sql
    self.connect()
  File "apps/frappe/frappe/database/database.py", line 75, in connect
    self._conn = self.get_connection()
  File "apps/frappe/frappe/database/mariadb/database.py", line 75, in get_connection
    conn = pymysql.connect(
  File "env/lib/python3.9/site-packages/pymysql/connections.py", line 353, in __init__
    self.connect()
  File "env/lib/python3.9/site-packages/pymysql/connections.py", line 633, in connect
    self._request_authentication()
  File "env/lib/python3.9/site-packages/pymysql/connections.py", line 907, in _request_authentication
    auth_packet = self._read_packet()
  File "env/lib/python3.9/site-packages/pymysql/connections.py", line 725, in _read_packet
    packet.raise_for_error()
  File "env/lib/python3.9/site-packages/pymysql/protocol.py", line 221, in raise_for_error
    err.raise_mysql_exception(self._data)
  File "env/lib/python3.9/site-packages/pymysql/err.py", line 143, in raise_mysql_exception
    raise errorclass(errno, errval)
pymysql.err.OperationalError: (1045, "Access denied for user '_95acf9e769041055'@'localhost' (using password: YES)")

/bin/sh: env/bin/bench: No such file or directory
Backup failed for Site library.test. Database or site_config.json may be corrupted
Traceback (most recent call last):
  File "apps/frappe/frappe/commands/site.py", line 580, in backup
    odb = scheduled_backup(
  File "apps/frappe/frappe/utils/backups.py", line 552, in scheduled_backup
    odb = new_backup(
  File "apps/frappe/frappe/utils/backups.py", line 586, in new_backup
    odb = BackupGenerator(
  File "apps/frappe/frappe/utils/backups.py", line 87, in __init__
    self.setup_backup_tables()
  File "apps/frappe/frappe/utils/backups.py", line 121, in setup_backup_tables
    existing_tables = frappe.db.get_tables()
  File "apps/frappe/frappe/database/database.py", line 879, in get_tables
    table_rows = self.sql("""
  File "apps/frappe/frappe/database/database.py", line 130, in sql
    self.connect()
  File "apps/frappe/frappe/database/database.py", line 75, in connect
    self._conn = self.get_connection()
  File "apps/frappe/frappe/database/mariadb/database.py", line 75, in get_connection
    conn = pymysql.connect(
  File "env/lib/python3.9/site-packages/pymysql/connections.py", line 353, in __init__
    self.connect()
  File "env/lib/python3.9/site-packages/pymysql/connections.py", line 633, in connect
    self._request_authentication()
  File "env/lib/python3.9/site-packages/pymysql/connections.py", line 907, in _request_authentication
    auth_packet = self._read_packet()
  File "env/lib/python3.9/site-packages/pymysql/connections.py", line 725, in _read_packet
    packet.raise_for_error()
  File "env/lib/python3.9/site-packages/pymysql/protocol.py", line 221, in raise_for_error
    err.raise_mysql_exception(self._data)
  File "env/lib/python3.9/site-packages/pymysql/err.py", line 143, in raise_mysql_exception
    raise errorclass(errno, errval)
pymysql.err.OperationalError: (1045, "Access denied for user '_95acf9e769041055'@'localhost' (using password: YES)")

/bin/sh: env/bin/bench: No such file or directory
Backup failed for Site library.test. Database or site_config.json may be corrupted
Traceback (most recent call last):
  File "apps/frappe/frappe/commands/site.py", line 580, in backup
    odb = scheduled_backup(
  File "apps/frappe/frappe/utils/backups.py", line 552, in scheduled_backup
    odb = new_backup(
  File "apps/frappe/frappe/utils/backups.py", line 586, in new_backup
    odb = BackupGenerator(
  File "apps/frappe/frappe/utils/backups.py", line 87, in __init__
    self.setup_backup_tables()
  File "apps/frappe/frappe/utils/backups.py", line 121, in setup_backup_tables
    existing_tables = frappe.db.get_tables()
  File "apps/frappe/frappe/database/database.py", line 879, in get_tables
    table_rows = self.sql("""
  File "apps/frappe/frappe/database/database.py", line 130, in sql
    self.connect()
  File "apps/frappe/frappe/database/database.py", line 75, in connect
    self._conn = self.get_connection()
  File "apps/frappe/frappe/database/mariadb/database.py", line 75, in get_connection
    conn = pymysql.connect(
  File "env/lib/python3.9/site-packages/pymysql/connections.py", line 353, in __init__
    self.connect()
  File "env/lib/python3.9/site-packages/pymysql/connections.py", line 633, in connect
    self._request_authentication()
  File "env/lib/python3.9/site-packages/pymysql/connections.py", line 907, in _request_authentication
    auth_packet = self._read_packet()
  File "env/lib/python3.9/site-packages/pymysql/connections.py", line 725, in _read_packet
    packet.raise_for_error()
  File "env/lib/python3.9/site-packages/pymysql/protocol.py", line 221, in raise_for_error
    err.raise_mysql_exception(self._data)
  File "env/lib/python3.9/site-packages/pymysql/err.py", line 143, in raise_mysql_exception
    raise errorclass(errno, errval)
pymysql.err.OperationalError: (1045, "Access denied for user '_95acf9e769041055'@'localhost' (using password: YES)")

/bin/sh: env/bin/bench: No such file or directory
Backup failed for Site library.test. Database or site_config.json may be corrupted
Traceback (most recent call last):
  File "apps/frappe/frappe/commands/site.py", line 580, in backup
    odb = scheduled_backup(
  File "apps/frappe/frappe/utils/backups.py", line 552, in scheduled_backup
    odb = new_backup(
  File "apps/frappe/frappe/utils/backups.py", line 586, in new_backup
    odb = BackupGenerator(
  File "apps/frappe/frappe/utils/backups.py", line 87, in __init__
    self.setup_backup_tables()
  File "apps/frappe/frappe/utils/backups.py", line 121, in setup_backup_tables
    existing_tables = frappe.db.get_tables()
  File "apps/frappe/frappe/database/database.py", line 879, in get_tables
    table_rows = self.sql("""
  File "apps/frappe/frappe/database/database.py", line 130, in sql
    self.connect()
  File "apps/frappe/frappe/database/database.py", line 75, in connect
    self._conn = self.get_connection()
  File "apps/frappe/frappe/database/mariadb/database.py", line 75, in get_connection
    conn = pymysql.connect(
  File "env/lib/python3.9/site-packages/pymysql/connections.py", line 353, in __init__
    self.connect()
  File "env/lib/python3.9/site-packages/pymysql/connections.py", line 633, in connect
    self._request_authentication()
  File "env/lib/python3.9/site-packages/pymysql/connections.py", line 907, in _request_authentication
    auth_packet = self._read_packet()
  File "env/lib/python3.9/site-packages/pymysql/connections.py", line 725, in _read_packet
    packet.raise_for_error()
  File "env/lib/python3.9/site-packages/pymysql/protocol.py", line 221, in raise_for_error
    err.raise_mysql_exception(self._data)
  File "env/lib/python3.9/site-packages/pymysql/err.py", line 143, in raise_mysql_exception
    raise errorclass(errno, errval)
pymysql.err.OperationalError: (1045, "Access denied for user '_95acf9e769041055'@'localhost' (using password: YES)")

/bin/sh: env/bin/bench: No such file or directory
Backup failed for Site library.test. Database or site_config.json may be corrupted
Traceback (most recent call last):
  File "apps/frappe/frappe/commands/site.py", line 580, in backup
    odb = scheduled_backup(
  File "apps/frappe/frappe/utils/backups.py", line 552, in scheduled_backup
    odb = new_backup(
  File "apps/frappe/frappe/utils/backups.py", line 586, in new_backup
    odb = BackupGenerator(
  File "apps/frappe/frappe/utils/backups.py", line 87, in __init__
    self.setup_backup_tables()
  File "apps/frappe/frappe/utils/backups.py", line 121, in setup_backup_tables
    existing_tables = frappe.db.get_tables()
  File "apps/frappe/frappe/database/database.py", line 879, in get_tables
    table_rows = self.sql("""
  File "apps/frappe/frappe/database/database.py", line 130, in sql
    self.connect()
  File "apps/frappe/frappe/database/database.py", line 75, in connect
    self._conn = self.get_connection()
  File "apps/frappe/frappe/database/mariadb/database.py", line 75, in get_connection
    conn = pymysql.connect(
  File "env/lib/python3.9/site-packages/pymysql/connections.py", line 353, in __init__
    self.connect()
  File "env/lib/python3.9/site-packages/pymysql/connections.py", line 633, in connect
    self._request_authentication()
  File "env/lib/python3.9/site-packages/pymysql/connections.py", line 907, in _request_authentication
    auth_packet = self._read_packet()
  File "env/lib/python3.9/site-packages/pymysql/connections.py", line 725, in _read_packet
    packet.raise_for_error()
  File "env/lib/python3.9/site-packages/pymysql/protocol.py", line 221, in raise_for_error
    err.raise_mysql_exception(self._data)
  File "env/lib/python3.9/site-packages/pymysql/err.py", line 143, in raise_mysql_exception
    raise errorclass(errno, errval)
pymysql.err.OperationalError: (1045, "Access denied for user '_95acf9e769041055'@'localhost' (using password: YES)")

/bin/sh: env/bin/bench: No such file or directory
Backup failed for Site library.test. Database or site_config.json may be corrupted
Traceback (most recent call last):
  File "apps/frappe/frappe/commands/site.py", line 580, in backup
    odb = scheduled_backup(
  File "apps/frappe/frappe/utils/backups.py", line 552, in scheduled_backup
    odb = new_backup(
  File "apps/frappe/frappe/utils/backups.py", line 586, in new_backup
    odb = BackupGenerator(
  File "apps/frappe/frappe/utils/backups.py", line 87, in __init__
    self.setup_backup_tables()
  File "apps/frappe/frappe/utils/backups.py", line 121, in setup_backup_tables
    existing_tables = frappe.db.get_tables()
  File "apps/frappe/frappe/database/database.py", line 879, in get_tables
    table_rows = self.sql("""
  File "apps/frappe/frappe/database/database.py", line 130, in sql
    self.connect()
  File "apps/frappe/frappe/database/database.py", line 75, in connect
    self._conn = self.get_connection()
  File "apps/frappe/frappe/database/mariadb/database.py", line 75, in get_connection
    conn = pymysql.connect(
  File "env/lib/python3.9/site-packages/pymysql/connections.py", line 353, in __init__
    self.connect()
  File "env/lib/python3.9/site-packages/pymysql/connections.py", line 633, in connect
    self._request_authentication()
  File "env/lib/python3.9/site-packages/pymysql/connections.py", line 907, in _request_authentication
    auth_packet = self._read_packet()
  File "env/lib/python3.9/site-packages/pymysql/connections.py", line 725, in _read_packet
    packet.raise_for_error()
  File "env/lib/python3.9/site-packages/pymysql/protocol.py", line 221, in raise_for_error
    err.raise_mysql_exception(self._data)
  File "env/lib/python3.9/site-packages/pymysql/err.py", line 143, in raise_mysql_exception
    raise errorclass(errno, errval)
pymysql.err.OperationalError: (1045, "Access denied for user '_95acf9e769041055'@'localhost' (using password: YES)")

/bin/sh: env/bin/bench: No such file or directory
Backup failed for Site library.test. Database or site_config.json may be corrupted
Traceback (most recent call last):
  File "apps/frappe/frappe/commands/site.py", line 580, in backup
    odb = scheduled_backup(
  File "apps/frappe/frappe/utils/backups.py", line 552, in scheduled_backup
    odb = new_backup(
  File "apps/frappe/frappe/utils/backups.py", line 586, in new_backup
    odb = BackupGenerator(
  File "apps/frappe/frappe/utils/backups.py", line 87, in __init__
    self.setup_backup_tables()
  File "apps/frappe/frappe/utils/backups.py", line 121, in setup_backup_tables
    existing_tables = frappe.db.get_tables()
  File "apps/frappe/frappe/database/database.py", line 879, in get_tables
    table_rows = self.sql("""
  File "apps/frappe/frappe/database/database.py", line 130, in sql
    self.connect()
  File "apps/frappe/frappe/database/database.py", line 75, in connect
    self._conn = self.get_connection()
  File "apps/frappe/frappe/database/mariadb/database.py", line 75, in get_connection
    conn = pymysql.connect(
  File "env/lib/python3.9/site-packages/pymysql/connections.py", line 353, in __init__
    self.connect()
  File "env/lib/python3.9/site-packages/pymysql/connections.py", line 633, in connect
    self._request_authentication()
  File "env/lib/python3.9/site-packages/pymysql/connections.py", line 907, in _request_authentication
    auth_packet = self._read_packet()
  File "env/lib/python3.9/site-packages/pymysql/connections.py", line 725, in _read_packet
    packet.raise_for_error()
  File "env/lib/python3.9/site-packages/pymysql/protocol.py", line 221, in raise_for_error
    err.raise_mysql_exception(self._data)
  File "env/lib/python3.9/site-packages/pymysql/err.py", line 143, in raise_mysql_exception
    raise errorclass(errno, errval)
pymysql.err.OperationalError: (1045, "Access denied for user '_95acf9e769041055'@'localhost' (using password: YES)")

